#VRML_SIM R2019b utf8
WorldInfo {
  contactProperties [
    ContactProperties {
      material1 "robotBody"
      material2 "floor"
      coulombFriction [
        0
      ]
    }
  ]
}
Viewpoint {
  orientation 0.9877595790122544 0.12824170884855682 0.08879796270825145 5.0603821219670175
  position 0.3613281921921514 2.987688116975954 0.9550427541252928
}
TexturedBackground {
}
TexturedBackgroundLight {
}
Floor {
}
Robot {
  translation 0 0.075 0
  children [
    DEF GR_BODY Group {
      children [
        DEF ROBOT_BODY Shape {
          appearance PBRAppearance {
            baseColor 0.933333 0.933333 0.9254899999999999
          }
          geometry DEF G_BODY Box {
            size 0.25 0.07 0.1
          }
        }
        Transform {
          translation 0.11 -0.054 0
          children [
            Shape {
              appearance PBRAppearance {
                baseColor 0.7999999999999999 0 0
                roughness 1
                metalness 0
              }
              geometry Sphere {
                radius 0.02
              }
            }
          ]
        }
      ]
    }
    DEF WHEEL1_JOINT HingeJoint {
      jointParameters HingeJointParameters {
        axis 0 0 1
        anchor -0.05 0 0.06
      }
      device [
        PositionSensor {
          name "encoder1"
        }
        RotationalMotor {
          name "motor_right"
        }
      ]
      endPoint DEF WHEEL1 Solid {
        translation -0.049993298639710804 4.1991004434008365e-06 0.059998844022989384
        rotation -0.9999897256320203 0.00320538877059385 -0.003205325759751868 1.570810065190105
        children [
          DEF SH_WHEEL Shape {
            appearance PBRAppearance {
              baseColor 0 0 0
              roughness 1
              metalness 0
            }
            geometry DEF G_WHEEL Cylinder {
              height 0.02
              radius 0.075
            }
          }
        ]
        boundingObject USE G_WHEEL
        physics Physics {
        }
      }
    }
    DEF WHEEL2_JOINT HingeJoint {
      jointParameters HingeJointParameters {
        axis 0 0 1
        anchor -0.05 0 -0.06
      }
      device [
        RotationalMotor {
          name "motor_left"
        }
      ]
      endPoint DEF WHEEL2 Solid {
        translation -0.05000464053569955 -4.475340648047137e-06 -0.06000114527398893
        rotation -0.9999897819929816 0.00319650948351654 -0.0031965976835833165 1.5708098619478401
        children [
          USE SH_WHEEL
        ]
        name "solid(1)"
        boundingObject USE SH_WHEEL
        physics Physics {
        }
      }
    }
    DistanceSensor {
      translation 0.125 0 -0.03
      children [
        Shape {
          appearance PBRAppearance {
            baseColor 0.7999999999999999 0 0
          }
          geometry Sphere {
            radius 0.01
          }
        }
      ]
      name "distance_sensor"
      lookupTable [
        0 0 0
        0.02 0 0
        5 1659 0
      ]
      resolution 1
    }
    DistanceSensor {
      translation 0.125 0 0.03
      children [
        Shape {
          appearance PBRAppearance {
            baseColor 0.7999999999999999 0 0
          }
          geometry Sphere {
            radius 0.01
          }
        }
      ]
      name "distance_sensor2"
      lookupTable [
        0 0 0
        0.02 0 0
        5 1659 0
      ]
      resolution 1
    }
  ]
  contactMaterial ""
  boundingObject USE GR_BODY
  physics Physics {
    mass 1
    centerOfMass [
      0 0 0
    ]
  }
  controller "ROBOT_EX34"
}
Solid {
  translation 0.728494 0.049999999999999996 0.249936
  children [
    Shape {
      appearance PBRAppearance {
        baseColor 0.3607843137254902 0.20784313725490197 0.4
      }
      geometry DEF G_OBSTACLE1 Box {
        size 0.5 0.5 0.5
      }
    }
  ]
  boundingObject USE G_OBSTACLE1
}
